<?xml version='1.0'?>

<robot name="dd_robot">

<!--xacro:property name="hokuyo_size" value="0.05"-->

  <material name="Black">
    <color rgba="0.0 0.0 0.0 1.0"/>
  </material>

  <material name="Red">
    <color rgba="0.8 0.0 0.0 1.0"/>
  </material>

  <material name="White">
    <color rgba="1.0 1.0 1.0 1.0"/>
  </material>


  <material name="Blue">
    <color rgba="0.0 0.0 0.8 1.0"/>
  </material>


<!--dummy-->
<link name="dummy">
    <visual>
        <origin xyz="0 0 0" rpy="0 0 0" />
        <geometry>
            <box size="0.001 0.001 0.001" />
        </geometry>
    </visual>
  </link>
  <gazebo reference="dummy">
    <turnGravityOff>false</turnGravityOff>
  </gazebo>

<!--dumm_joint-->
  <joint name="dummy_joint" type="fixed">
    <origin xyz="0 0 0.175" rpy="0 0 0"/>
     <parent link="dummy"/>
     <child link="base_link"/>
  </joint>

  <!-- Base Link -->
  <link name="base_link">
    <visual>
      <origin xyz="0 0 0" rpy="0 0 0" />
      <geometry>
          <box size="0.8 0.5 0.25"/>
      </geometry>
      <material name="Blue" />
    </visual>
    
    <!-- Base collision, mass and inertia -->
    <collision>
      <origin xyz="0 0 0" rpy="0 0 0" />
      <geometry>
          <box size="0.8 0.5 0.25"/>
      </geometry>
    </collision>
    <inertial>
      <mass value="5"/>
      <inertia ixx="0.13" ixy="0.0" ixz="0.0" iyy="0.37" iyz="0.0" izz="0.29"/>
    </inertial>
  </link>

    <!-- Caster -->
    <link name="caster_link">
    <visual>
      <origin xyz="0 0 0" rpy="0 0 0" />
      <geometry>
        <sphere radius="0.05" />
      </geometry>
      <material name="Black" />
    </visual>
    <!-- Caster collision, mass and inertia -->
    <collision>
      <origin xyz="0 0 0" rpy="0 0 0" />
      <geometry>
        <sphere radius="0.05" />
      </geometry>
    </collision>
    <inertial>
      <mass value="0.5"/>
      <inertia ixx="0.0005" ixy="0.0" ixz="0.0" iyy="0.0005" iyz="0.0" izz="0.0005"/>
    </inertial>
  </link>

  <!--Caster_joint-->
  <joint name="caster_joint" type="fixed">
    <origin xyz="0.345 0 -0.125" rpy="0 0 0"/>
     <parent link="base_link"/>
     <child link="caster_link"/>
  </joint>
  
  <!-- Right Wheel -->
  <link name="right_wheel">
    <visual>
      <origin xyz="0 0 0" rpy="1.570795 0 0" />
      <geometry>
          <cylinder length="0.1" radius="0.2" />
      </geometry>
      <material name="Black" />
    </visual>

    <!-- Right Wheel collision, mass and inertia -->
    <collision>
      <origin xyz="0 0 0" rpy="1.570795 0 0" />
      <geometry>
          <cylinder length="0.1" radius="0.2" />
      </geometry>
    </collision>
    <inertial>
      <mass value="0.5"/>
      <inertia ixx="0.01" ixy="0.0" ixz="0.0" iyy="0.005" iyz="0.0" izz="0.005"/>
    </inertial>

  </link>


  <!-- Right Wheel joint -->
  <joint name="joint_right_wheel" type="continuous">
    <parent link="base_link"/>
    <child link="right_wheel"/>
    <origin xyz="-0.15 -0.30 0.025" rpy="0 0 0" /> 
    <axis xyz="0 1 0" />
  </joint>
  
  <!-- Left Wheel -->
  <link name="left_wheel">
    <visual>
      <origin xyz="0 0 0" rpy="1.570795 0 0" />
      <geometry>
          <cylinder length="0.1" radius="0.2" />
      </geometry>
      <material name="Black" />
    </visual>

    <!-- Left Wheel collision, mass and inertia -->
    <collision>
      <origin xyz="0 0 0" rpy="1.570795 0 0" />
      <geometry>
          <cylinder length="0.1" radius="0.2" />
      </geometry>
    </collision>
    <inertial>
      <mass value="0.5"/>
      <inertia ixx="0.01" ixy="0.0" ixz="0.0" iyy="0.005" iyz="0.0" izz="0.005"/>
    </inertial>

  </link>


  <!-- Left Wheel joint -->
  <joint name="joint_left_wheel" type="continuous">
    <parent link="base_link"/>
    <child link="left_wheel"/>
    <origin xyz="-0.15 0.30 0.025" rpy="0 0 0" /> 
    <axis xyz="0 1 0"/>
  </joint>

  <!--LIDAR-->
  <link name="hokuyo_link">
    <visual>
      <origin xyz="0 0 0" rpy="0 0 0" />
      <geometry>
        <box size="0.05 0.05 0.05"/>
      </geometry>
      <material name="White" />
    </visual>
  </link>
  <joint name="hokuyo_joint" type="fixed">
    <origin xyz="0.38 0 0.1375" rpy="0 0 0" />
    <parent link="base_link"/>
    <child link="hokuyo_link" />
  </joint>

</robot>
  